Workbook
Name Emp_Data: Class_3_File!$A$1:$AF$101
Name Slicer_Dept_Name: #N/A
Name Slicer_Region: #N/A

Sheet HR_Data
A1: Emp_ID | B1: Date_of_Birth | C1: Age | D1: Hire_Date | E1: Hiring Source | F1: Dept_ID | G1: Job_Title | H1: Employment_Type | I1: Manager_ID | J1: Base_Salary | K1: Bonus | L1: Total_Salary | M1: Years_of_Experience | N1: Performance_Rating | O1: Attendance_Percentage | P1: Certifications | Q1: Promotion_Eligible | R1: Attrition_Risk | S1: Last_Promotion_Date | T1: Employee_Status | U1: First_Name | V1: Last_Name | W1: Full_Name | X1: ID_Card_Details | Y1: Dept_Name | Z1: Diwali_Month_Salary | AA1: Salary_Seg | AB1: Gender | AC1: Education_Level | AD1: Location | AE1: Region | AF1: Advanced_Cert_Bonus
A2: EMP075 | B2: 31339 | C2: 39 | D2: 41983 | E2: Referral | F2: D_006 | G2: VP Finance | H2: Full-Time | I2: MGR103 | J2: 1450000 | K2: 165000 | L2: =SUM(J2:K2) -> 1615000 | M2: 19 | N2: 4.8 | O2: 99.1 | P2: 4 | Q2: No | R2: Low | S2: 43819 | T2: Active | U2: =VLOOKUP(A2,Emp_Info!$B$1:$G$101,3,0) -> vinay | V2: =_xlfn.XLOOKUP(A2,Emp_Info!$B$2:$B$101,Emp_Info!$A$2:$A$101,,0) -> reddy | W2: =PROPER(_xlfn.CONCAT(U2," ",V2)) -> Vinay Reddy | X2: =UPPER(_xlfn.CONCAT(LEFT(U2),LEFT(V2),RIGHT(A2,3))) -> VR075 | Y2: =HLOOKUP(F2,Dept_Info!$A$2:$I$3,2,0) -> Finance | Z2: =IF(Y2="Sales",L2+(L2*$AG$6),L2) -> 1615000 | AA2: =IF(J2<700000,"Low",IF(AND(J2>700000,J2<900000),"Medium","High")) -> High | AB2: Male | AC2: =INDEX(Emp_Info!$B$1:$G$101,MATCH(HR_Data!$A18,Emp_Info!$B$2:$B$101,0),MATCH(HR_Data!AC$1,Emp_Info!$B$1:$G$1,0)) -> Bachelor | AD2: =INDEX(Emp_Info!$A$1:$G$101,MATCH(HR_Data!$A2,Emp_Info!$B$1:$B$101,0),MATCH(HR_Data!AD$1,Emp_Info!$A$1:$G$1,0)) -> Chennai | AE2: =INDEX(Emp_Info!$A$1:$G$101,MATCH(HR_Data!$A2,Emp_Info!$B$1:$B$101,0),MATCH(HR_Data!AE$1,Emp_Info!$A$1:$G$1,0)) -> South | AF2: =IF(AND(P2>=3,M2>6),"Eligible","Not Eligible") -> Eligible | AG2: HR
A3: EMP019 | B3: 31301 | C3: 39 | D3: 42070 | E3: Job Portal | F3: D_001 | G3: IT Manager | H3: Full-Time | I3: MGR101 | J3: 1450000 | K3: 165000 | L3: =SUM(J3:K3) -> 1615000 | M3: 17 | N3: 4.8 | O3: 99.2 | P3: 5 | Q3: No | R3: Low | S3: 43905 | T3: Active | U3: =VLOOKUP(A3,Emp_Info!$B$1:$G$101,3,0) -> anil | V3: =_xlfn.XLOOKUP(A3,Emp_Info!$B$2:$B$101,Emp_Info!$A$2:$A$101,,0) -> chopra | W3: =PROPER(_xlfn.CONCAT(U3," ",V3)) -> Anil Chopra | X3: =UPPER(_xlfn.CONCAT(LEFT(U3),LEFT(V3),RIGHT(A3,3))) -> AC019 | Y3: =HLOOKUP(F3,Dept_Info!$A$2:$I$3,2,0) -> IT | Z3: =IF(Y3="Sales",L3+(L3*$AG$6),L3) -> 1615000 | AA3: =IF(J3<700000,"Low",IF(AND(J3>700000,J3<900000),"Medium","High")) -> High | AB3: Male | AC3: =INDEX(Emp_Info!$B$1:$G$101,MATCH(HR_Data!$A49,Emp_Info!$B$2:$B$101,0),MATCH(HR_Data!AC$1,Emp_Info!$B$1:$G$1,0)) -> Master | AD3: =INDEX(Emp_Info!$A$1:$G$101,MATCH(HR_Data!$A3,Emp_Info!$B$1:$B$101,0),MATCH(HR_Data!AD$1,Emp_Info!$A$1:$G$1,0)) -> Noida | AE3: =INDEX(Emp_Info!$A$1:$G$101,MATCH(HR_Data!$A3,Emp_Info!$B$1:$B$101,0),MATCH(HR_Data!AE$1,Emp_Info!$A$1:$G$1,0)) -> North | AF3: =IF(AND(P3>=3,M3>6),"Eligible","Not Eligible") -> Eligible
A4: EMP097 | B4: 31462 | D4: 42137 | E4: Referral | F4: D_003 | G4: VP Sales | H4: Full-Time | I4: MGR106 | J4: 1380000 | K4: 158000 | L4: =SUM(J4:K4) -> 1538000 | M4: 18 | N4: 4.8 | O4: 99 | P4: 4 | Q4: No | R4: Low | S4: 43971 | T4: Active | U4: =VLOOKUP(A4,Emp_Info!$B$1:$G$101,3,0) -> rohit | V4: =_xlfn.XLOOKUP(A4,Emp_Info!$B$2:$B$101,Emp_Info!$A$2:$A$101,,0) -> agarwal | W4: =PROPER(_xlfn.CONCAT(U4," ",V4)) -> Rohit Agarwal | X4: =UPPER(_xlfn.CONCAT(LEFT(U4),LEFT(V4),RIGHT(A4,3))) -> RA097 | Y4: =HLOOKUP(F4,Dept_Info!$A$2:$I$3,2,0) -> Sales | Z4: =IF(Y4="Sales",L4+(L4*$AG$6),L4) -> 1768700 | AA4: =IF(J4<700000,"Low",IF(AND(J4>700000,J4<900000),"Medium","High")) -> High | AB4: Male | AC4: =INDEX(Emp_Info!$B$1:$G$101,MATCH(HR_Data!$A86,Emp_Info!$B$2:$B$101,0),MATCH(HR_Data!AC$1,Emp_Info!$B$1:$G$1,0)) -> Master | AD4: =INDEX(Emp_Info!$A$1:$G$101,MATCH(HR_Data!$A4,Emp_Info!$B$1:$B$101,0),MATCH(HR_Data!AD$1,Emp_Info!$A$1:$G$1,0)) -> Bangalore | AE4: =INDEX(Emp_Info!$A$1:$G$101,MATCH(HR_Data!$A4,Emp_Info!$B$1:$B$101,0),MATCH(HR_Data!AE$1,Emp_Info!$A$1:$G$1,0)) -> South | AF4: =IF(AND(P4>=3,M4>6),"Eligible","Not Eligible") -> Eligible
A5: EMP005 | B5: 32129 | C5: 37 | D5: 42559 | E5: Campus | F5: D_005 | G5: Operations Manager | H5: Full-Time | I5: MGR105 | J5: 1100000 | K5: 120000 | L5: =SUM(J5:K5) -> 1220000 | M5: 15 | N5: 4.7 | O5: 99 | P5: 4 | Q5: No | R5: Low | S5: 44397 | T5: Active | U5: =VLOOKUP(A5,Emp_Info!$B$1:$G$101,3,0) -> vikram | V5: =_xlfn.XLOOKUP(A5,Emp_Info!$B$2:$B$101,Emp_Info!$A$2:$A$101,,0) -> singh | W5: =PROPER(_xlfn.CONCAT(U5," ",V5)) -> Vikram Singh | X5: =UPPER(_xlfn.CONCAT(LEFT(U5),LEFT(V5),RIGHT(A5,3))) -> VS005 | Y5: =HLOOKUP(F5,Dept_Info!$A$2:$I$3,2,0) -> Marketing | Z5: =IF(Y5="Sales",L5+(L5*$AG$6),L5) -> 1220000 | AA5: =IF(J5<700000,"Low",IF(AND(J5>700000,J5<900000),"Medium","High")) -> High | AB5: Male | AC5: =INDEX(Emp_Info!$B$1:$G$101,MATCH(HR_Data!$A73,Emp_Info!$B$2:$B$101,0),MATCH(HR_Data!AC$1,Emp_Info!$B$1:$G$1,0)) -> Bachelor | AD5: =INDEX(Emp_Info!$A$1:$G$101,MATCH(HR_Data!$A5,Emp_Info!$B$1:$B$101,0),MATCH(HR_Data!AD$1,Emp_Info!$A$1:$G$1,0)) -> Pune | AE5: =INDEX(Emp_Info!$A$1:$G$101,MATCH(HR_Data!$A5,Emp_Info!$B$1:$B$101,0),MATCH(HR_Data!AE$1,Emp_Info!$A$1:$G$1,0)) -> West | AF5: =IF(AND(P5>=3,M5>6),"Eligible","Not Eligible") -> Eligible | AG5: Bonus
A6: EMP047 | B6: 31355 | C6: 39 | D6: 42115 | E6: LinkedIn | F6: D_005 | G6: Plant Manager | H6: Full-Time | I6: MGR105 | J6: 1080000 | K6: 115000 | L6: =SUM(J6:K6) -> 1195000 | M6: 18 | N6: 4.6 | O6: 98.6 | P6: 4 | Q6: No | R6: Low | S6: 43931 | T6: Active | U6: =VLOOKUP(A6,Emp_Info!$B$1:$G$101,3,0) -> rajeev | V6: =_xlfn.XLOOKUP(A6,Emp_Info!$B$2:$B$101,Emp_Info!$A$2:$A$101,,0) -> bose | W6: =PROPER(_xlfn.CONCAT(U6," ",V6)) -> Rajeev Bose | X6: =UPPER(_xlfn.CONCAT(LEFT(U6),LEFT(V6),RIGHT(A6,3))) -> RB047 | Y6: =HLOOKUP(F6,Dept_Info!$A$2:$I$3,2,0) -> Marketing | Z6: =IF(Y6="Sales",L6+(L6*$AG$6),L6) -> 1195000 | AA6: =IF(J6<700000,"Low",IF(AND(J6>700000,J6<900000),"Medium","High")) -> High | AB6: Male | AC6: =INDEX(Emp_Info!$B$1:$G$101,MATCH(HR_Data!$A70,Emp_Info!$B$2:$B$101,0),MATCH(HR_Data!AC$1,Emp_Info!$B$1:$G$1,0)) -> Bachelor | AD6: =INDEX(Emp_Info!$A$1:$G$101,MATCH(HR_Data!$A6,Emp_Info!$B$1:$B$101,0),MATCH(HR_Data!AD$1,Emp_Info!$A$1:$G$1,0)) -> Pune | AE6: =INDEX(Emp_Info!$A$1:$G$101,MATCH(HR_Data!$A6,Emp_Info!$B$1:$B$101,0),MATCH(HR_Data!AE$1,Emp_Info!$A$1:$G$1,0)) -> West | AF6: =IF(AND(P6>=3,M6>6),"Eligible","Not Eligible") -> Eligible | AG6: 0.15
A7: EMP041 | B7: 33015 | C7: 34 | D7: 43419 | E7: Freelance | F7: D_001 | G7: Cloud Architect | H7: Full-Time | I7: MGR101 | J7: 1050000 | K7: 110000 | L7: =SUM(J7:K7) -> 1160000 | M7: 11 | N7: 4.7 | O7: 98.9 | P7: 5 | Q7: Yes | R7: Low | S7: 44885 | T7: Active | U7: =VLOOKUP(A7,Emp_Info!$B$1:$G$101,3,0) -> varun | V7: =_xlfn.XLOOKUP(A7,Emp_Info!$B$2:$B$101,Emp_Info!$A$2:$A$101,,0) -> kapoor | W7: =PROPER(_xlfn.CONCAT(U7," ",V7)) -> Varun Kapoor | X7: =UPPER(_xlfn.CONCAT(LEFT(U7),LEFT(V7),RIGHT(A7,3))) -> VK041 | Y7: =HLOOKUP(F7,Dept_Info!$A$2:$I$3,2,0) -> IT | Z7: =IF(Y7="Sales",L7+(L7*$AG$6),L7) -> 1160000 | AA7: =IF(J7<700000,"Low",IF(AND(J7>700000,J7<900000),"Medium","High")) -> High | AB7: Male | AC7: =INDEX(Emp_Info!$B$1:$G$101,MATCH(HR_Data!$A55,Emp_Info!$B$2:$B$101,0),MATCH(HR_Data!AC$1,Emp_Info!$B$1:$G$1,0)) -> Bachelor | AD7: =INDEX(Emp_Info!$A$1:$G$101,MATCH(HR_Data!$A7,Emp_Info!$B$1:$B$101,0),MATCH(HR_Data!AD$1,Emp_Info!$A$1:$G$1,0)) -> Noida | AE7: =INDEX(Emp_Info!$A$1:$G$101,MATCH(HR_Data!$A7,Emp_Info!$B$1:$B$101,0),MATCH(HR_Data!AE$1,Emp_Info!$A$1:$G$1,0)) -> North | AF7: =IF(AND(P7>=3,M7>6),"Eligible","Not Eligible") -> Eligible
A8: EMP009 | B8: 31654 | C8: 38 | D8: 42040 | E8: Referral | F8: D_006 | G8: Finance Manager | H8: Full-Time | I8: MGR103 | J8: 1050000 | K8: 105000 | L8: =SUM(J8:K8) -> 1155000 | M8: 16 | N8: 4.6 | O8: 98.5 | P8: 3 | Q8: No | R8: Low | S8: 43871 | T8: Active | U8: =VLOOKUP(A8,Emp_Info!$B$1:$G$101,3,0) -> suresh | V8: =_xlfn.XLOOKUP(A8,Emp_Info!$B$2:$B$101,Emp_Info!$A$2:$A$101,,0) -> nair | W8: =PROPER(_xlfn.CONCAT(U8," ",V8)) -> Suresh Nair | X8: =UPPER(_xlfn.CONCAT(LEFT(U8),LEFT(V8),RIGHT(A8,3))) -> SN009 | Y8: =HLOOKUP(F8,Dept_Info!$A$2:$I$3,2,0) -> Finance | Z8: =IF(Y8="Sales",L8+(L8*$AG$6),L8) -> 1155000 | AA8: =IF(J8<700000,"Low",IF(AND(J8>700000,J8<900000),"Medium","High")) -> High | AB8: Male | AC8: =INDEX(Emp_Info!$B$1:$G$101,MATCH(HR_Data!$A20,Emp_Info!$B$2:$B$101,0),MATCH(HR_Data!AC$1,Emp_Info!$B$1:$G$1,0)) -> Master | AD8: =INDEX(Emp_Info!$A$1:$G$101,MATCH(HR_Data!$A8,Emp_Info!$B$1:$B$101,0),MATCH(HR_Data!AD$1,Emp_Info!$A$1:$G$1,0)) -> Chennai | AE8: =INDEX(Emp_Info!$A$1:$G$101,MATCH(HR_Data!$A8,Emp_Info!$B$1:$B$101,0),MATCH(HR_Data!AE$1,Emp_Info!$A$1:$G$1,0)) -> South | AF8: =IF(AND(P8>=3,M8>6),"Eligible","Not Eligible") -> Eligible
A9: EMP079 | B9: 32516 | C9: 35 | D9: 43329 | E9: Job Portal | F9: D_003 | G9: National Sales Manager | H9: Full-Time | I9: MGR106 | J9: 1020000 | K9: 125000 | L9: =SUM(J9:K9) -> 1145000 | M9: 12 | N9: 4.7 | O9: 98.6 | P9: 3 | Q9: Yes | R9: Low | S9: 45163 | T9: Active | U9: =VLOOKUP(A9,Emp_Info!$B$1:$G$101,3,0) -> nikhil | V9: =_xlfn.XLOOKUP(A9,Emp_Info!$B$2:$B$101,Emp_Info!$A$2:$A$101,,0) -> chopra | W9: =PROPER(_xlfn.CONCAT(U9," ",V9)) -> Nikhil Chopra | X9: =UPPER(_xlfn.CONCAT(LEFT(U9),LEFT(V9),RIGHT(A9,3))) -> NC079 | Y9: =HLOOKUP(F9,Dept_Info!$A$2:$I$3,2,0) -> Sales | Z9: =IF(Y9="Sales",L9+(L9*$AG$6),L9) -> 1316750 | AA9: =IF(J9<700000,"Low",IF(AND(J9>700000,J9<900000),"Medium","High")) -> High | AB9: Male | AC9: =INDEX(Emp_Info!$B$1:$G$101,MATCH(HR_Data!$A92,Emp_Info!$B$2:$B$101,0),MATCH(HR_Data!AC$1,Emp_Info!$B$1:$G$1,0)) -> Master | AD9: =INDEX(Emp_Info!$A$1:$G$101,MATCH(HR_Data!$A9,Emp_Info!$B$1:$B$101,0),MATCH(HR_Data!AD$1,Emp_Info!$A$1:$G$1,0)) -> Hyderabad | AE9: =INDEX(Emp_Info!$A$1:$G$101,MATCH(HR_Data!$A9,Emp_Info!$B$1:$B$101,0),MATCH(HR_Data!AE$1,Emp_Info!$A$1:$G$1,0)) -> South | AF9: =IF(AND(P9>=3,M9>6),"Eligible","Not Eligible") -> Eligible
A10: EMP051 | B10: 31537 | C10: 38 | D10: 42383 | E10: Freelance | F10: D_006 | G10: Controller | H10: Full-Time | I10: MGR103 | J10: 980000 | K10: 98000 | L10: =SUM(J10:K10) -> 1078000 | M10: 16 | N10: 4.5 | O10: 98.2 | P10: 3 | Q10: No | R10: Low | S10: 44216 | T10: Active | U10: =VLOOKUP(A10,Emp_Info!$B$1:$G$101,3,0) -> ramesh | V10: =_xlfn.XLOOKUP(A10,Emp_Info!$B$2:$B$101,Emp_Info!$A$2:$A$101,,0) -> pillai | W10: =PROPER(_xlfn.CONCAT(U10," ",V10)) -> Ramesh Pillai | X10: =UPPER(_xlfn.CONCAT(LEFT(U10),LEFT(V10),RIGHT(A10,3))) -> RP051 | Y10: =HLOOKUP(F10,Dept_Info!$A$2:$I$3,2,0) -> Finance | Z10: =IF(Y10="Sales",L10+(L10*$AG$6),L10) -> 1078000 | AA10: =IF(J10<700000,"Low",IF(AND(J10>700000,J10<900000),"Medium","High")) -> High | AB10: Male | AC10: =INDEX(Emp_Info!$B$1:$G$101,MATCH(HR_Data!$A21,Emp_Info!$B$2:$B$101,0),MATCH(HR_Data!AC$1,Emp_Info!$B$1:$G$1,0)) -> Master | AD10: =INDEX(Emp_Info!$A$1:$G$101,MATCH(HR_Data!$A10,Emp_Info!$B$1:$B$101,0),MATCH(HR_Data!AD$1,Emp_Info!$A$1:$G$1,0)) -> Chennai | AE10: =INDEX(Emp_Info!$A$1:$G$101,MATCH(HR_Data!$A10,Emp_Info!$B$1:$B$101,0),MATCH(HR_Data!AE$1,Emp_Info!$A$1:$G$1,0)) -> South | AF10: =IF(AND(P10>=3,M10>6),"Eligible","Not Eligible") -> Eligible
A11: EMP077 | B11: 32276 | C11: 36 | D11: 43053 | E11: LinkedIn | F11: D_001 | G11: Solutions Architect | H11: Full-Time | I11: MGR101 | J11: 980000 | K11: 98000 | L11: =SUM(J11:K11) -> 1078000 | M11: 13 | N11: 4.6 | O11: 98.4 | P11: 4 | Q11: Yes | R11: Low | S11: 44885 | T11: Active | U11: =VLOOKUP(A11,Emp_Info!$B$1:$G$101,3,0) -> rajat | V11: =_xlfn.XLOOKUP(A11,Emp_Info!$B$2:$B$101,Emp_Info!$A$2:$A$101,,0) -> verma | W11: =PROPER(_xlfn.CONCAT(U11," ",V11)) -> Rajat Verma | X11: =UPPER(_xlfn.CONCAT(LEFT(U11),LEFT(V11),RIGHT(A11,3))) -> RV077 | Y11: =HLOOKUP(F11,Dept_Info!$A$2:$I$3,2,0) -> IT | Z11: =IF(Y11="Sales",L11+(L11*$AG$6),L11) -> 1078000 | AA11: =IF(J11<700000,"Low",IF(AND(J11>700000,J11<900000),"Medium","High")) -> High | AB11: Male | AC11: =INDEX(Emp_Info!$B$1:$G$101,MATCH(HR_Data!$A53,Emp_Info!$B$2:$B$101,0),MATCH(HR_Data!AC$1,Emp_Info!$B$1:$G$1,0)) -> Master | AD11: =INDEX(Emp_Info!$A$1:$G$101,MATCH(HR_Data!$A11,Emp_Info!$B$1:$B$101,0),MATCH(HR_Data!AD$1,Emp_Info!$A$1:$G$1,0)) -> Delhi | AE11: =INDEX(Emp_Info!$A$1:$G$101,MATCH(HR_Data!$A11,Emp_Info!$B$1:$B$101,0),MATCH(HR_Data!AE$1,Emp_Info!$A$1:$G$1,0)) -> North | AF11: =IF(AND(P11>=3,M11>6),"Eligible","Not Eligible") -> Eligible
A12: EMP025 | B12: 33206 | C12: 34 | D12: 43544 | E12: Job Portal | F12: D_003 | G12: Regional Sales Manager | H12: Full-Time | I12: MGR106 | J12: 950000 | K12: 115000 | L12: =SUM(J12:K12) -> 1065000 | M12: 10 | N12: 4.5 | O12: 97.8 | P12: 2 | Q12: Yes | R12: Low | S12: 44995 | T12: Active | U12: =VLOOKUP(A12,Emp_Info!$B$1:$G$101,3,0) -> gaurav | V12: =_xlfn.XLOOKUP(A12,Emp_Info!$B$2:$B$101,Emp_Info!$A$2:$A$101,,0) -> pandey | W12: =PROPER(_xlfn.CONCAT(U12," ",V12)) -> Gaurav Pandey | X12: =UPPER(_xlfn.CONCAT(LEFT(U12),LEFT(V12),RIGHT(A12,3))) -> GP025 | Y12: =HLOOKUP(F12,Dept_Info!$A$2:$I$3,2,0) -> Sales | Z12: =IF(Y12="Sales",L12+(L12*$AG$6),L12) -> 1224750 | AA12: =IF(J12<700000,"Low",IF(AND(J12>700000,J12<900000),"Medium","High")) -> High | AB12: Male | AC12: =INDEX(Emp_Info!$B$1:$G$101,MATCH(HR_Data!$A95,Emp_Info!$B$2:$B$101,0),MATCH(HR_Data!AC$1,Emp_Info!$B$1:$G$1,0)) -> Master | AD12: =INDEX(Emp_Info!$A$1:$G$101,MATCH(HR_Data!$A12,Emp_Info!$B$1:$B$101,0),MATCH(HR_Data!AD$1,Emp_Info!$A$1:$G$1,0)) -> Hyderabad | AE12: =INDEX(Emp_Info!$A$1:$G$101,MATCH(HR_Data!$A12,Emp_Info!$B$1:$B$101,0),MATCH(HR_Data!AE$1,Emp_Info!$A$1:$G$1,0)) -> South | AF12: =IF(AND(P12>=3,M12>6),"Eligible","Not Eligible") -> Not Eligible
A13: EMP061 | B13: 32504 | C13: 36 | D13: 42954 | E13: Referral | F13: D_003 | G13: Enterprise Sales Manager | H13: Full-Time | I13: MGR106 | J13: 940000 | K13: 112000 | L13: =SUM(J13:K13) -> 1052000 | M13: 13 | N13: 4.5 | O13: 98.1 | P13: 3 | Q13: Yes | R13: Low | S13: 44788 | T13: Active | U13: =VLOOKUP(A13,Emp_Info!$B$1:$G$101,3,0) -> siddharth | V13: =_xlfn.XLOOKUP(A13,Emp_Info!$B$2:$B$101,Emp_Info!$A$2:$A$101,,0) -> mehta | W13: =PROPER(_xlfn.CONCAT(U13," ",V13)) -> Siddharth Mehta | X13: =UPPER(_xlfn.CONCAT(LEFT(U13),LEFT(V13),RIGHT(A13,3))) -> SM061 | Y13: =HLOOKUP(F13,Dept_Info!$A$2:$I$3,2,0) -> Sales | Z13: =IF(Y13="Sales",L13+(L13*$AG$6),L13) -> 1209800 | AA13: =IF(J13<700000,"Low",IF(AND(J13>700000,J13<900000),"Medium","High")) -> High | AB13: Male | AC13: =INDEX(Emp_Info!$B$1:$G$101,MATCH(HR_Data!$A91,Emp_Info!$B$2:$B$101,0),MATCH(HR_Data!AC$1,Emp_Info!$B$1:$G$1,0)) -> Bachelor | AD13: =INDEX(Emp_Info!$A$1:$G$101,MATCH(HR_Data!$A13,Emp_Info!$B$1:$B$101,0),MATCH(HR_Data!AD$1,Emp_Info!$A$1:$G$1,0)) -> Delhi | AE13: =INDEX(Emp_Info!$A$1:$G$101,MATCH(HR_Data!$A13,Emp_Info!$B$1:$B$101,0),MATCH(HR_Data!AE$1,Emp_Info!$A$1:$G$1,0)) -> North | AF13: =IF(AND(P13>=3,M13>6),"Eligible","Not Eligible") -> Eligible
A14: EMP002 | B14: 33076 | C14: 34 | D14: 43631 | E14: LinkedIn | F14: D_002 | G14: HR Manager | H14: Full-Time | I14: MGR102 | J14: 950000 | K14: 95000 | L14: =SUM(J14:K14) -> 1045000 | M14: 10 | N14: 4.3 | O14: 98.2 | P14: 2 | Q14: Yes | R14: Low | S14: 45087 | T14: Active | U14: =VLOOKUP(A14,Emp_Info!$B$1:$G$101,3,0) -> priya | V14: =_xlfn.XLOOKUP(A14,Emp_Info!$B$2:$B$101,Emp_Info!$A$2:$A$101,,0) -> sharma | W14: =PROPER(_xlfn.CONCAT(U14," ",V14)) -> Priya Sharma | X14: =UPPER(_xlfn.CONCAT(LEFT(U14),LEFT(V14),RIGHT(A14,3))) -> PS002 | Y14: =HLOOKUP(F14,Dept_Info!$A$2:$I$3,2,0) -> HR | Z14: =IF(Y14="Sales",L14+(L14*$AG$6),L14) -> 1045000 | AA14: =IF(J14<700000,"Low",IF(AND(J14>700000,J14<900000),"Medium","High")) -> High | AB14: Female | AC14: =INDEX(Emp_Info!$B$1:$G$101,MATCH(HR_Data!$A35,Emp_Info!$B$2:$B$101,0),MATCH(HR_Data!AC$1,Emp_Info!$B$1:$G$1,0)) -> Bachelor | AD14: =INDEX(Emp_Info!$A$1:$G$101,MATCH(HR_Data!$A14,Emp_Info!$B$1:$B$101,0),MATCH(HR_Data!AD$1,Emp_Info!$A$1:$G$1,0)) -> Delhi | AE14: =INDEX(Emp_Info!$A$1:$G$101,MATCH(HR_Data!$A14,Emp_Info!$B$1:$B$101,0),MATCH(HR_Data!AE$1,Emp_Info!$A$1:$G$1,0)) -> North | AF14: =IF(AND(P14>=3,M14>6),"Eligible","Not Eligible") -> Not Eligible
A15: EMP092 | B15: 34168 | C15: 31 | D15: 44462 | E15: Job Portal | F15: D_001 | G15: Machine Learning Engineer | H15: Full-Time | I15: MGR101 | J15: 950000 | K15: 95000 | L15: =SUM(J15:K15) -> 1045000 | M15: 6 | N15: 4.6 | O15: 98.3 | P15: 4 | Q15: Yes | R15: Low | S15: NA | T15: Active | U15: =VLOOKUP(A15,Emp_Info!$B$1:$G$101,3,0) -> kavita | V15: =_xlfn.XLOOKUP(A15,Emp_Info!$B$2:$B$101,Emp_Info!$A$2:$A$101,,0) -> pillai | W15: =PROPER(_xlfn.CONCAT(U15," ",V15)) -> Kavita Pillai | X15: =UPPER(_xlfn.CONCAT(LEFT(U15),LEFT(V15),RIGHT(A15,3))) -> KP092 | Y15: =HLOOKUP(F15,Dept_Info!$A$2:$I$3,2,0) -> IT | Z15: =IF(Y15="Sales",L15+(L15*$AG$6),L15) -> 1045000 | AA15: =IF(J15<700000,"Low",IF(AND(J15>700000,J15<900000),"Medium","High")) -> High | AB15: Female | AC15: =INDEX(Emp_Info!$B$1:$G$101,MATCH(HR_Data!$A61,Emp_Info!$B$2:$B$101,0),MATCH(HR_Data!AC$1,Emp_Info!$B$1:$G$1,0)) -> Bachelor | AD15: =INDEX(Emp_Info!$A$1:$G$101,MATCH(HR_Data!$A15,Emp_Info!$B$1:$B$101,0),MATCH(HR_Data!AD$1,Emp_Info!$A$1:$G$1,0)) -> Bangalore | AE15: =INDEX(Emp_Info!$A$1:$G$101,MATCH(HR_Data!$A15,Emp_Info!$B$1:$B$101,0),MATCH(HR_Data!AE$1,Emp_Info!$A$1:$G$1,0)) -> South | AF15: =IF(AND(P15>=3,M15>6),"Eligible","Not Eligible") -> Not Eligible
A16: EMP036 | B16: 33490 | C16: 33 | D16: 43851 | E16: Referral | F16: D_004 | G16: Product Manager | H16: Full-Time | I16: MGR104 | J16: 920000 | K16: 95000 | L16: =SUM(J16:K16) -> 1015000 | M16: 9 | N16: 4.6 | O16: 98.7 | P16: 3 | Q16: Yes | R16: Low | S16: NA | T16: Active | U16: =VLOOKUP(A16,Emp_Info!$B$1:$G$101,3,0) -> pallavi | V16: =_xlfn.XLOOKUP(A16,Emp_Info!$B$2:$B$101,Emp_Info!$A$2:$A$101,,0) -> nambiar | W16: =PROPER(_xlfn.CONCAT(U16," ",V16)) -> Pallavi Nambiar | X16: =UPPER(_xlfn.CONCAT(LEFT(U16),LEFT(V16),RIGHT(A16,3))) -> PN036 | Y16: =HLOOKUP(F16,Dept_Info!$A$2:$I$3,2,0) -> Admin | Z16: =IF(Y16="Sales",L16+(L16*$AG$6),L16) -> 1015000 | AA16: =IF(J16<700000,"Low",IF(AND(J16>700000,J16<900000),"Medium","High")) -> High | AB16: Female | AC16: =INDEX(Emp_Info!$B$1:$G$101,MATCH(HR_Data!$A3,Emp_Info!$B$2:$B$101,0),MATCH(HR_Data!AC$1,Emp_Info!$B$1:$G$1,0)) -> Bachelor | AD16: =INDEX(Emp_Info!$A$1:$G$101,MATCH(HR_Data!$A16,Emp_Info!$B$1:$B$101,0),MATCH(HR_Data!AD$1,Emp_Info!$A$1:$G$1,0)) -> Pune | AE16: =INDEX(Emp_Info!$A$1:$G$101,MATCH(HR_Data!$A16,Emp_Info!$B$1:$B$101,0),MATCH(HR_Data!AE$1,Emp_Info!$A$1:$G$1,0)) -> West | AF16: =IF(AND(P16>=3,M16>6),"Eligible","Not Eligible") -> Eligible
A17: EMP011 | B17: 30684 | C17: 40 | D17: 41988 | E17: Freelance | F17: D_001 | G17: Senior Developer | H17: Full-Time | I17: MGR101 | J17: 920000 | K17: 92000 | L17: =SUM(J17:K17) -> 1012000 | M17: 18 | N17: 4.4 | O17: 97.3 | P17: 4 | Q17: No | R17: Low | S17: 43819 | T17: Active | U17: =VLOOKUP(A17,Emp_Info!$B$1:$G$101,3,0) -> manoj | V17: =_xlfn.XLOOKUP(A17,Emp_Info!$B$2:$B$101,Emp_Info!$A$2:$A$101,,0) -> gupta | W17: =PROPER(_xlfn.CONCAT(U17," ",V17)) -> Manoj Gupta | X17: =UPPER(_xlfn.CONCAT(LEFT(U17),LEFT(V17),RIGHT(A17,3))) -> MG011 | Y17: =HLOOKUP(F17,Dept_Info!$A$2:$I$3,2,0) -> IT | Z17: =IF(Y17="Sales",L17+(L17*$AG$6),L17) -> 1012000 | AA17: =IF(J17<700000,"Low",IF(AND(J17>700000,J17<900000),"Medium","High")) -> High | AB17: Male | AC17: =INDEX(Emp_Info!$B$1:$G$101,MATCH(HR_Data!$A48,Emp_Info!$B$2:$B$101,0),MATCH(HR_Data!AC$1,Emp_Info!$B$1:$G$1,0)) -> Bachelor | AD17: =INDEX(Emp_Info!$A$1:$G$101,MATCH(HR_Data!$A17,Emp_Info!$B$1:$B$101,0),MATCH(HR_Data!AD$1,Emp_Info!$A$1:$G$1,0)) -> Noida | AE17: =INDEX(Emp_Info!$A$1:$G$101,MATCH(HR_Data!$A17,Emp_Info!$B$1:$B$101,0),MATCH(HR_Data!AE$1,Emp_Info!$A$1:$G$1,0)) -> North | AF17: =IF(AND(P17>=3,M17>6),"Eligible","Not Eligible") -> Eligible
A18: EMP059 | B18: 31479 | C18: 38 | D18: 42300 | E18: Job Portal | F18: D_005 | G18: Production Manager | H18: Full-Time | I18: MGR105 | J18: 920000 | K18: 92000 | L18: =SUM(J18:K18) -> 1012000 | M18: 17 | N18: 4.4 | O18: 97.9 | P18: 3 | Q18: No | R18: Low | S18: 44119 | T18: Active | U18: =VLOOKUP(A18,Emp_Info!$B$1:$G$101,3,0) -> alok | V18: =_xlfn.XLOOKUP(A18,Emp_Info!$B$2:$B$101,Emp_Info!$A$2:$A$101,,0) -> sinha | W18: =PROPER(_xlfn.CONCAT(U18," ",V18)) -> Alok Sinha | X18: =UPPER(_xlfn.CONCAT(LEFT(U18),LEFT(V18),RIGHT(A18,3))) -> AS059 | Y18: =HLOOKUP(F18,Dept_Info!$A$2:$I$3,2,0) -> Marketing | Z18: =IF(Y18="Sales",L18+(L18*$AG$6),L18) -> 1012000 | AA18: =IF(J18<700000,"Low",IF(AND(J18>700000,J18<900000),"Medium","High")) -> High | AB18: Male | AC18: =INDEX(Emp_Info!$B$1:$G$101,MATCH(HR_Data!$A71,Emp_Info!$B$2:$B$101,0),MATCH(HR_Data!AC$1,Emp_Info!$B$1:$G$1,0)) -> Master | AD18: =INDEX(Emp_Info!$A$1:$G$101,MATCH(HR_Data!$A18,Emp_Info!$B$1:$B$101,0),MATCH(HR_Data!AD$1,Emp_Info!$A$1:$G$1,0)) -> Chennai | AE18: =INDEX(Emp_Info!$A$1:$G$101,MATCH(HR_Data!$A18,Emp_Info!$B$1:$B$101,0),MATCH(HR_Data!AE$1,Emp_Info!$A$1:$G$1,0)) -> South | AF18: =IF(AND(P18>=3,M18>6),"Eligible","Not Eligible") -> Eligible
A19: EMP093 | B19: 32080 | C19: 37 | D19: 42531 | E19: Freelance | F19: D_006 | G19: Financial Planning Manager | H19: Full-Time | I19: MGR103 | J19: 920000 | K19: 92000 | L19: =SUM(J19:K19) -> 1012000 | M19: 15 | N19: 4.5 | O19: 98 | P19: 3 | Q19: Yes | R19: Low | S19: 44367 | T19: Active | U19: =VLOOKUP(A19,Emp_Info!$B$1:$G$101,3,0) -> dinesh | V19: =_xlfn.XLOOKUP(A19,Emp_Info!$B$2:$B$101,Emp_Info!$A$2:$A$101,,0) -> reddy | W19: =PROPER(_xlfn.CONCAT(U19," ",V19)) -> Dinesh Reddy | X19: =UPPER(_xlfn.CONCAT(LEFT(U19),LEFT(V19),RIGHT(A19,3))) -> DR093 | Y19: =HLOOKUP(F19,Dept_Info!$A$2:$I$3,2,0) -> Finance | Z19: =IF(Y19="Sales",L19+(L19*$AG$6),L19) -> 1012000 | AA19: =IF(J19<700000,"Low",IF(AND(J19>700000,J19<900000),"Medium","High")) -> High | AB19: Male | AC19: =INDEX(Emp_Info!$B$1:$G$101,MATCH(HR_Data!$A23,Emp_Info!$B$2:$B$101,0),MATCH(HR_Data!AC$1,Emp_Info!$B$1:$G$1,0)) -> Master | AD19: =INDEX(Emp_Info!$A$1:$G$101,MATCH(HR_Data!$A19,Emp_Info!$B$1:$B$101,0),MATCH(HR_Data!AD$1,Emp_Info!$A$1:$G$1,0)) -> Delhi | AE19: =INDEX(Emp_Info!$A$1:$G$101,MATCH(HR_Data!$A19,Emp_Info!$B$1:$B$101,0),MATCH(HR_Data!AE$1,Emp_Info!$A$1:$G$1,0)) -> North | AF19: =IF(AND(P19>=3,M19>6),"Eligible","Not Eligible") -> Eligible
A20: EMP096 | B20: 33579 | C20: 33 | D20: 43758 | E20: Freelance | F20: D_001 | G20: Technical Lead | H20: Full-Time | I20: MGR101 | J20: 920000 | K20: 92000 | L20: =SUM(J20:K20) -> 1012000 | M20: 9 | N20: 4.5 | O20: 98.1 | P20: 4 | Q20: Yes | R20: Low | S20: 45214 | T20: Active | U20: =VLOOKUP(A20,Emp_Info!$B$1:$G$101,3,0) -> anjana | V20: =_xlfn.XLOOKUP(A20,Emp_Info!$B$2:$B$101,Emp_Info!$A$2:$A$101,,0) -> nair | W20: =PROPER(_xlfn.CONCAT(U20," ",V20)) -> Anjana Nair | X20: =UPPER(_xlfn.CONCAT(LEFT(U20),LEFT(V20),RIGHT(A20,3))) -> AN096 | Y20: =HLOOKUP(F20,Dept_Info!$A$2:$I$3,2,0) -> IT | Z20: =IF(Y20="Sales",L20+(L20*$AG$6),L20) -> 1012000 | AA20: =IF(J20<700000,"Low",IF(AND(J20>700000,J20<900000),"Medium","High")) -> High | AB20: Female | AC20: =INDEX(Emp_Info!$B$1:$G$101,MATCH(HR_Data!$A56,Emp_Info!$B$2:$B$101,0),MATCH(HR_Data!AC$1,Emp_Info!$B$1:$G$1,0)) -> Master | AD20: =INDEX(Emp_Info!$A$1:$G$101,MATCH(HR_Data!$A20,Emp_Info!$B$1:$B$101,0),MATCH(HR_Data!AD$1,Emp_Info!$A$1:$G$1,0)) -> Noida | AE20: =INDEX(Emp_Info!$A$1:$G$101,MATCH(HR_Data!$A20,Emp_Info!$B$1:$B$101,0),MATCH(HR_Data!AE$1,Emp_Info!$A$1:$G$1,0)) -> North | AF20: =IF(AND(P20>=3,M20>6),"Eligible","Not Eligible") -> Eligible
A21: EMP082 | B21: 34530 | C21: 30 | D21: 44862 | E21: Job Portal | F21: D_001 | G21: Data Scientist | H21: Full-Time | I21: MGR101 | J21: 920000 | K21: 92000 | L21: =SUM(J21:K21) -> 1012000 | M21: 5 | N21: 4.5 | O21: 97.8 | P21: 3 | Q21: Yes | R21: Low | S21: NA | T21: Active | U21: =VLOOKUP(A21,Emp_Info!$B$1:$G$101,3,0) -> namita | V21: =_xlfn.XLOOKUP(A21,Emp_Info!$B$2:$B$101,Emp_Info!$A$2:$A$101,,0) -> rao | W21: =PROPER(_xlfn.CONCAT(U21," ",V21)) -> Namita Rao | X21: =UPPER(_xlfn.CONCAT(LEFT(U21),LEFT(V21),RIGHT(A21,3))) -> NR082 | Y21: =HLOOKUP(F21,Dept_Info!$A$2:$I$3,2,0) -> IT | Z21: =IF(Y21="Sales",L21+(L21*$AG$6),L21) -> 1012000 | AA21: =IF(J21<700000,"Low",IF(AND(J21>700000,J21<900000),"Medium","High")) -> High | AB21: Female | AC21: =INDEX(Emp_Info!$B$1:$G$101,MATCH(HR_Data!$A63,Emp_Info!$B$2:$B$101,0),MATCH(HR_Data!AC$1,Emp_Info!$B$1:$G$1,0)) -> Master | AD21: =INDEX(Emp_Info!$A$1:$G$101,MATCH(HR_Data!$A21,Emp_Info!$B$1:$B$101,0),MATCH(HR_Data!AD$1,Emp_Info!$A$1:$G$1,0)) -> Noida | AE21: =INDEX(Emp_Info!$A$1:$G$101,MATCH(HR_Data!$A21,Emp_Info!$B$1:$B$101,0),MATCH(HR_Data!AE$1,Emp_Info!$A$1:$G$1,0)) -> North | AF21: =IF(AND(P21>=3,M21>6),"Eligible","Not Eligible") -> Not Eligible
A22: EMP049 | B22: 32199 | C22: 36 | D22: 42622 | E22: Freelance | F22: D_003 | G22: Channel Sales Manager | H22: Full-Time | I22: MGR106 | J22: 890000 | K22: 105000 | L22: =SUM(J22:K22) -> 995000 | M22: 14 | N22: 4.4 | O22: 97.5 | P22: 3 | Q22: Yes | R22: Low | S22: 44459 | T22: Active | U22: =VLOOKUP(A22,Emp_Info!$B$1:$G$101,3,0) -> sunil | V22: =_xlfn.XLOOKUP(A22,Emp_Info!$B$2:$B$101,Emp_Info!$A$2:$A$101,,0) -> agarwal | W22: =PROPER(_xlfn.CONCAT(U22," ",V22)) -> Sunil Agarwal | X22: =UPPER(_xlfn.CONCAT(LEFT(U22),LEFT(V22),RIGHT(A22,3))) -> SA049 | Y22: =HLOOKUP(F22,Dept_Info!$A$2:$I$3,2,0) -> Sales | Z22: =IF(Y22="Sales",L22+(L22*$AG$6),L22) -> 1144250 | AA22: =IF(J22<700000,"Low",IF(AND(J22>700000,J22<900000),"Medium","High")) -> Medium | AB22: Male | AC22: =INDEX(Emp_Info!$B$1:$G$101,MATCH(HR_Data!$A90,Emp_Info!$B$2:$B$101,0),MATCH(HR_Data!AC$1,Emp_Info!$B$1:$G$1,0)) -> Bachelor | AD22: =INDEX(Emp_Info!$A$1:$G$101,MATCH(HR_Data!$A22,Emp_Info!$B$1:$B$101,0),MATCH(HR_Data!AD$1,Emp_Info!$A$1:$G$1,0)) -> Bangalore | AE22: =INDEX(Emp_Info!$A$1:$G$101,MATCH(HR_Data!$A22,Emp_Info!$B$1:$B$101,0),MATCH(HR_Data!AE$1,Emp_Info!$A$1:$G$1,0)) -> South | AF22: =IF(AND(P22>=3,M22>6),"Eligible","Not Eligible") -> Eligible
A23: EMP007 | B23: 32673 | C23: 35 | D23: 43434 | E23: Job Portal | F23: D_003 | G23: Sales Manager | H23: Full-Time | I23: MGR106 | J23: 880000 | K23: 110000 | L23: =SUM(J23:K23) -> 990000 | M23: 11 | N23: 4.3 | O23: 96.7 | P23: 1 | Q23: Yes | R23: Medium | S23: 44880 | T23: Active | U23: =VLOOKUP(A23,Emp_Info!$B$1:$G$101,3,0) -> rahul | V23: =_xlfn.XLOOKUP(A23,Emp_Info!$B$2:$B$101,Emp_Info!$A$2:$A$101,,0) -> mehta | W23: =PROPER(_xlfn.CONCAT(U23," ",V23)) -> Rahul Mehta | X23: =UPPER(_xlfn.CONCAT(LEFT(U23),LEFT(V23),RIGHT(A23,3))) -> RM007 | Y23: =HLOOKUP(F23,Dept_Info!$A$2:$I$3,2,0) -> Sales | Z23: =IF(Y23="Sales",L23+(L23*$AG$6),L23) -> 1138500 | AA23: =IF(J23<700000,"Low",IF(AND(J23>700000,J23<900000),"Medium","High")) -> Medium | AB23: Male | AC23: =INDEX(Emp_Info!$B$1:$G$101,MATCH(HR_Data!$A94,Emp_Info!$B$2:$B$101,0),MATCH(HR_Data!AC$1,Emp_Info!$B$1:$G$1,0)) -> Bachelor | AD23: =INDEX(Emp_Info!$A$1:$G$101,MATCH(HR_Data!$A23,Emp_Info!$B$1:$B$101,0),MATCH(HR_Data!AD$1,Emp_Info!$A$1:$G$1,0)) -> Delhi | AE23: =INDEX(Emp_Info!$A$1:$G$101,MATCH(HR_Data!$A23,Emp_Info!$B$1:$B$101,0),MATCH(HR_Data!AE$1,Emp_Info!$A$1:$G$1,0)) -> North | AF23: =IF(AND(P23>=3,M23>6),"Eligible","Not Eligible") -> Not Eligible
A24: EMP099 | B24: 32308 | C24: 36 | D24: 43048 | E24: Referral | F24: D_006 | G24: Mergers & Acquisitions Analyst | H24: Full-Time | I24: MGR103 | J24: 890000 | K24: 88000 | L24: =SUM(J24:K24) -> 978000 | M24: 13 | N24: 4.4 | O24: 97.6 | P24: 3 | Q24: Yes | R24: Low | S24: 44885 | T24: Active | U24: =VLOOKUP(A24,Emp_Info!$B$1:$G$101,3,0) -> vikas | V24: =_xlfn.XLOOKUP(A24,Emp_Info!$B$2:$B$101,Emp_Info!$A$2:$A$101,,0) -> sharma | W24: =PROPER(_xlfn.CONCAT(U24," ",V24)) -> Vikas Sharma | X24: =UPPER(_xlfn.CONCAT(LEFT(U24),LEFT(V24),RIGHT(A24,3))) -> VS099 | Y24: =HLOOKUP(F24,Dept_Info!$A$2:$I$3,2,0) -> Finance | Z24: =IF(Y24="Sales",L24+(L24*$AG$6),L24) -> 978000 | AA24: =IF(J24<700000,"Low",IF(AND(J24>700000,J24<900000),"Medium","High")) -> Medium | AB24: Male | AC24: =INDEX(Emp_Info!$B$1:$G$101,MATCH(HR_Data!$A27,Emp_Info!$B$2:$B$101,0),MATCH(HR_Data!AC$1,Emp_Info!$B$1:$G$1,0)) -> Master | AD24: =INDEX(Emp_Info!$A$1:$G$101,MATCH(HR_Data!$A24,Emp_Info!$B$1:$B$101,0),MATCH(HR_Data!AD$1,Emp_Info!$A$1:$G$1,0)) -> Pune | AE24: =INDEX(Emp_Info!$A$1:$G$101,MATCH(HR_Data!$A24,Emp_Info!$B$1:$B$101,0),MATCH(HR_Data!AE$1,Emp_Info!$A$1:$G$1,0)) -> West | AF24: =IF(AND(P24>=3,M24>6),"Eligible","Not Eligible") -> Eligible
A25: EMP029 | B25: 32485 | D25: 42903 | E25: LinkedIn | F25: D_005 | G25: Process Manager | H25: Full-Time | I25: MGR105 | J25: 890000 | K25: 88000 | L25: =SUM(J25:K25) -> 978000 | M25: 13 | N25: 4.3 | O25: 98 | P25: 3 | Q25: Yes | R25: Low | S25: 44732 | T25: Active | U25: =VLOOKUP(A25,Emp_Info!$B$1:$G$101,3,0) -> nitin | V25: =_xlfn.XLOOKUP(A25,Emp_Info!$B$2:$B$101,Emp_Info!$A$2:$A$101,,0) -> jain | W25: =PROPER(_xlfn.CONCAT(U25," ",V25)) -> Nitin Jain | X25: =UPPER(_xlfn.CONCAT(LEFT(U25),LEFT(V25),RIGHT(A25,3))) -> NJ029 | Y25: =HLOOKUP(F25,Dept_Info!$A$2:$I$3,2,0) -> Marketing | Z25: =IF(Y25="Sales",L25+(L25*$AG$6),L25) -> 978000 | AA25: =IF(J25<700000,"Low",IF(AND(J25>700000,J25<900000),"Medium","High")) -> Medium | AB25: Male | AC25: =INDEX(Emp_Info!$B$1:$G$101,MATCH(HR_Data!$A78,Emp_Info!$B$2:$B$101,0),MATCH(HR_Data!AC$1,Emp_Info!$B$1:$G$1,0)) -> Bachelor | AD25: =INDEX(Emp_Info!$A$1:$G$101,MATCH(HR_Data!$A25,Emp_Info!$B$1:$B$101,0),MATCH(HR_Data!AD$1,Emp_Info!$A$1:$G$1,0)) -> Pune | AE25: =INDEX(Emp_Info!$A$1:$G$101,MATCH(HR_Data!$A25,Emp_Info!$B$1:$B$101,0),MATCH(HR_Data!AE$1,Emp_Info!$A$1:$G$1,0)) -> West | AF25: =IF(AND(P25>=3,M25>6),"Eligible","Not Eligible") -> Eligible
A26: EMP091 | B26: 32514 | C26: 35 | D26: 43084 | E26: LinkedIn | F26: D_003 | G26: Direct Sales Manager | H26: Full-Time | I26: MGR106 | J26: 870000 | K26: 98000 | L26: =SUM(J26:K26) -> 968000 | M26: 12 | N26: 4.4 | O26: 97.4 | P26: 2 | Q26: Yes | R26: Low | S26: 44915 | T26: Active | U26: =VLOOKUP(A26,Emp_Info!$B$1:$G$101,3,0) -> sameer | V26: =_xlfn.XLOOKUP(A26,Emp_Info!$B$2:$B$101,Emp_Info!$A$2:$A$101,,0) -> bansal | W26: =PROPER(_xlfn.CONCAT(U26," ",V26)) -> Sameer Bansal | X26: =UPPER(_xlfn.CONCAT(LEFT(U26),LEFT(V26),RIGHT(A26,3))) -> SB091 | Y26: =HLOOKUP(F26,Dept_Info!$A$2:$I$3,2,0) -> Sales | Z26: =IF(Y26="Sales",L26+(L26*$AG$6),L26) -> 1113200 | AA26: =IF(J26<700000,"Low",IF(AND(J26>700000,J26<900000),"Medium","High")) -> Medium | AB26: Male | AC26: =INDEX(Emp_Info!$B$1:$G$101,MATCH(HR_Data!$A93,Emp_Info!$B$2:$B$101,0),MATCH(HR_Data!AC$1,Emp_Info!$B$1:$G$1,0)) -> Master | AD26: =INDEX(Emp_Info!$A$1:$G$101,MATCH(HR_Data!$A26,Emp_Info!$B$1:$B$101,0),MATCH(HR_Data!AD$1,Emp_Info!$A$1:$G$1,0)) -> Pune | AE26: =INDEX(Emp_Info!$A$1:$G$101,MATCH(HR_Data!$A26,Emp_Info!$B$1:$B$101,0),MATCH(HR_Data!AE$1,Emp_Info!$A$1:$G$1,0)) -> West | AF26: =IF(AND(P26>=3,M26>6),"Eligible","Not Eligible") -> Not Eligible
A27: EMP037 | B27: 31471 | C27: 38 | D27: 42342 | E27: Job Portal | F27: D_001 | G27: DevOps Engineer | H27: Full-Time | I27: MGR101 | J27: 880000 | K27: 85000 | L27: =SUM(J27:K27) -> 965000 | M27: 16 | N27: 4.4 | O27: 97.4 | P27: 4 | Q27: No | R27: Low | S27: 44180 | T27: Active | U27: =VLOOKUP(A27,Emp_Info!$B$1:$G$101,3,0) -> ajay | V27: =_xlfn.XLOOKUP(A27,Emp_Info!$B$2:$B$101,Emp_Info!$A$2:$A$101,,0) -> sharma | W27: =PROPER(_xlfn.CONCAT(U27," ",V27)) -> Ajay Sharma | X27: =UPPER(_xlfn.CONCAT(LEFT(U27),LEFT(V27),RIGHT(A27,3))) -> AS037 | Y27: =HLOOKUP(F27,Dept_Info!$A$2:$I$3,2,0) -> IT | Z27: =IF(Y27="Sales",L27+(L27*$AG$6),L27) -> 965000 | AA27: =IF(J27<700000,"Low",IF(AND(J27>700000,J27<900000),"Medium","High")) -> Medium | AB27: Male | AC27: =INDEX(Emp_Info!$B$1:$G$101,MATCH(HR_Data!$A50,Emp_Info!$B$2:$B$101,0),MATCH(HR_Data!AC$1,Emp_Info!$B$1:$G$1,0)) -> Bachelor | AD27: =INDEX(Emp_Info!$A$1:$G$101,MATCH(HR_Data!$A27,Emp_Info!$B$1:$B$101,0),MATCH(HR_Data!AD$1,Emp_Info!$A$1:$G$1,0)) -> Bangalore | AE27: =INDEX(Emp_Info!$A$1:$G$101,MATCH(HR_Data!$A27,Emp_Info!$B$1:$B$101,0),MATCH(HR_Data!AE$1,Emp_Info!$A$1:$G$1,0)) -> South | AF27: =IF(AND(P27>=3,M27>6),"Eligible","Not Eligible") -> Eligible
A28: EMP086 | B28: 33453 | C28: 33 | D28: 43795 | E28: Job Portal | F28: D_001 | G28: Product Owner | H28: Full-Time | I28: MGR101 | J28: 880000 | K28: 85000 | L28: =SUM(J28:K28) -> 965000 | M28: 9 | N28: 4.4 | O28: 97.6 | P28: 3 | Q28: Yes | R28: Low | S28: NA | T28: Active | U28: =VLOOKUP(A28,Emp_Info!$B$1:$G$101,3,0) -> preeti | V28: =_xlfn.XLOOKUP(A28,Emp_Info!$B$2:$B$101,Emp_Info!$A$2:$A$101,,0) -> menon | W28: =PROPER(_xlfn.CONCAT(U28," ",V28)) -> Preeti Menon | X28: =UPPER(_xlfn.CONCAT(LEFT(U28),LEFT(V28),RIGHT(A28,3))) -> PM086 | Y28: =HLOOKUP(F28,Dept_Info!$A$2:$I$3,2,0) -> IT | Z28: =IF(Y28="Sales",L28+(L28*$AG$6),L28) -> 965000 | AA28: =IF(J28<700000,"Low",IF(AND(J28>700000,J28<900000),"Medium","High")) -> Medium | AB28: Female | AC28: =INDEX(Emp_Info!$B$1:$G$101,MATCH(HR_Data!$A59,Emp_Info!$B$2:$B$101,0),MATCH(HR_Data!AC$1,Emp_Info!$B$1:$G$1,0)) -> Bachelor | AD28: =INDEX(Emp_Info!$A$1:$G$101,MATCH(HR_Data!$A28,Emp_Info!$B$1:$B$101,0),MATCH(HR_Data!AD$1,Emp_Info!$A$1:$G$1,0)) -> Bangalore | AE28: =INDEX(Emp_Info!$A$1:$G$101,MATCH(HR_Data!$A28,Emp_Info!$B$1:$B$101,0),MATCH(HR_Data!AE$1,Emp_Info!$A$1:$G$1,0)) -> South | AF28: =IF(AND(P28>=3,M28>6),"Eligible","Not Eligible") -> Eligible
A29: EMP031 | B29: 31837 | C29: 37 | D29: 42680 | E29: Job Portal | F29: D_003 | G29: Key Account Manager | H29: Full-Time | I29: MGR106 | J29: 860000 | K29: 98000 | L29: =SUM(J29:K29) -> 958000 | M29: 14 | N29: 4.4 | O29: 96.9 | P29: 2 | Q29: Yes | R29: Low | S29: 44515 | T29: Active | U29: =VLOOKUP(A29,Emp_Info!$B$1:$G$101,3,0) -> ravi | V29: =_xlfn.XLOOKUP(A29,Emp_Info!$B$2:$B$101,Emp_Info!$A$2:$A$101,,0) -> shetty | W29: =PROPER(_xlfn.CONCAT(U29," ",V29)) -> Ravi Shetty | X29: =UPPER(_xlfn.CONCAT(LEFT(U29),LEFT(V29),RIGHT(A29,3))) -> RS031 | Y29: =HLOOKUP(F29,Dept_Info!$A$2:$I$3,2,0) -> Sales | Z29: =IF(Y29="Sales",L29+(L29*$AG$6),L29) -> 1101700 | AA29: =IF(J29<700000,"Low",IF(AND(J29>700000,J29<900000),"Medium","High")) -> Medium | AB29: Male | AC29: =INDEX(Emp_Info!$B$1:$G$101,MATCH(HR_Data!$A89,Emp_Info!$B$2:$B$101,0),MATCH(HR_Data!AC$1,Emp_Info!$B$1:$G$1,0)) -> Bachelor | AD29: =INDEX(Emp_Info!$A$1:$G$101,MATCH(HR_Data!$A29,Emp_Info!$B$1:$B$101,0),MATCH(HR_Data!AD$1,Emp_Info!$A$1:$G$1,0)) -> Bangalore | AE29: =INDEX(Emp_Info!$A$1:$G$101,MATCH(HR_Data!$A29,Emp_Info!$B$1:$B$101,0),MATCH(HR_Data!AE$1,Emp_Info!$A$1:$G$1,0)) -> South | AF29: =IF(AND(P29>=3,M29>6),"Eligible","Not Eligible") -> Not Eligible
A30: EMP017 | B30: 31871 | C30: 37 | D30: 42655 | E30: Referral | F30: D_005 | G30: Logistics Manager | H30: Full-Time | I30: MGR105 | J30: 870000 | K30: 85000 | L30: =SUM(J30:K30) -> 955000 | M30: 14 | N30: 4.3 | O30: 98.1 | P30: 3 | Q30: Yes | R30: Low | S30: 44489 | T30: Active | U30: =VLOOKUP(A30,Emp_Info!$B$1:$G$101,3,0) -> sanjay | V30: =_xlfn.XLOOKUP(A30,Emp_Info!$B$2:$B$101,Emp_Info!$A$2:$A$101,,0) -> pillai | W30: =PROPER(_xlfn.CONCAT(U30," ",V30)) -> Sanjay Pillai | X30: =UPPER(_xlfn.CONCAT(LEFT(U30),LEFT(V30),RIGHT(A30,3))) -> SP017 | Y30: =HLOOKUP(F30,Dept_Info!$A$2:$I$3,2,0) -> Marketing | Z30: =IF(Y30="Sales",L30+(L30*$AG$6),L30) -> 955000 | AA30: =IF(J30<700000,"Low",IF(AND(J30>700000,J30<900000),"Medium","High")) -> Medium | AB30: Male | AC30: =INDEX(Emp_Info!$B$1:$G$101,MATCH(HR_Data!$A77,Emp_Info!$B$2:$B$101,0),MATCH(HR_Data!AC$1,Emp_Info!$B$1:$G$1,0)) -> Bachelor | AD30: =INDEX(Emp_Info!$A$1:$G$101,MATCH(HR_Data!$A30,Emp_Info!$B$1:$B$101,0),MATCH(HR_Data!AD$1,Emp_Info!$A$1:$G$1,0)) -> Chennai | AE30: =INDEX(Emp_Info!$A$1:$G$101,MATCH(HR_Data!$A30,Emp_Info!$B$1:$B$101,0),MATCH(HR_Data!AE$1,Emp_Info!$A$1:$G$1,0)) -> South | AF30: =IF(AND(P30>=3,M30>6),"Eligible","Not Eligible") -> Eligible
A31: EMP081 | B31: 31718 | C31: 38 | D31: 42515 | E31: LinkedIn | F31: D_006 | G31: Compliance Officer | H31: Full-Time | I31: MGR103 | J31: 860000 | K31: 82000 | L31: =SUM(J31:K31) -> 942000 | M31: 16 | N31: 4.3 | O31: 97.1 | P31: 3 | Q31: No | R31: Low | S31: 44326 | T31: Active | U31: =VLOOKUP(A31,Emp_Info!$B$1:$G$101,3,0) -> sachin | V31: =_xlfn.XLOOKUP(A31,Emp_Info!$B$2:$B$101,Emp_Info!$A$2:$A$101,,0) -> desai | W31: =PROPER(_xlfn.CONCAT(U31," ",V31)) -> Sachin Desai | X31: =UPPER(_xlfn.CONCAT(LEFT(U31),LEFT(V31),RIGHT(A31,3))) -> SD081 | Y31: =HLOOKUP(F31,Dept_Info!$A$2:$I$3,2,0) -> Finance | Z31: =IF(Y31="Sales",L31+(L31*$AG$6),L31) -> 942000 | AA31: =IF(J31<700000,"Low",IF(AND(J31>700000,J31<900000),"Medium","High")) -> Medium | AB31: Male | AC31: =INDEX(Emp_Info!$B$1:$G$101,MATCH(HR_Data!$A22,Emp_Info!$B$2:$B$101,0),MATCH(HR_Data!AC$1,Emp_Info!$B$1:$G$1,0)) -> Bachelor | AD31: =INDEX(Emp_Info!$A$1:$G$101,MATCH(HR_Data!$A31,Emp_Info!$B$1:$B$101,0),MATCH(HR_Data!AD$1,Emp_Info!$A$1:$G$1,0)) -> Mumbai | AE31: =INDEX(Emp_Info!$A$1:$G$101,MATCH(HR_Data!$A31,Emp_Info!$B$1:$B$101,0),MATCH(HR_Data!AE$1,Emp_Info!$A$1:$G$1,0)) -> West | AF31: =IF(AND(P31>=3,M31>6),"Eligible","Not Eligible") -> Eligible
A32: EMP001 | B32: 31121 | C32: 39 | D32: 43191 | E32: Job Portal | F32: D_001 | G32: Software Engineer | H32: Full-Time | I32: MGR101 | J32: 850000 | K32: 85000 | L32: =SUM(J32:K32) -> 935000 | M32: 12 | N32: 4.2 | O32: 96.5 | P32: 3 | Q32: Yes | R32: Low | S32: 44666 | T32: Active | U32: =VLOOKUP(A32,Emp_Info!$B$1:$G$101,3,0) -> rajesh | V32: =_xlfn.XLOOKUP(A32,Emp_Info!$B$2:$B$101,Emp_Info!$A$2:$A$101,,0) -> kumar | W32: =PROPER(_xlfn.CONCAT(U32," ",V32)) -> Rajesh Kumar | X32: =UPPER(_xlfn.CONCAT(LEFT(U32),LEFT(V32),RIGHT(A32,3))) -> RK001 | Y32: =HLOOKUP(F32,Dept_Info!$A$2:$I$3,2,0) -> IT | Z32: =IF(Y32="Sales",L32+(L32*$AG$6),L32) -> 935000 | AA32: =IF(J32<700000,"Low",IF(AND(J32>700000,J32<900000),"Medium","High")) -> Medium | AB32: Male | AC32: =INDEX(Emp_Info!$B$1:$G$101,MATCH(HR_Data!$A54,Emp_Info!$B$2:$B$101,0),MATCH(HR_Data!AC$1,Emp_Info!$B$1:$G$1,0)) -> Bachelor | AD32: =INDEX(Emp_Info!$A$1:$G$101,MATCH(HR_Data!$A32,Emp_Info!$B$1:$B$101,0),MATCH(HR_Data!AD$1,Emp_Info!$A$1:$G$1,0)) -> Mumbai | AE32: =INDEX(Emp_Info!$A$1:$G$101,MATCH(HR_Data!$A32,Emp_Info!$B$1:$B$101,0),MATCH(HR_Data!AE$1,Emp_Info!$A$1:$G$1,0)) -> West | AF32: =IF(AND(P32>=3,M32>6),"Eligible","Not Eligible") -> Eligible
A33: EMP089 | B33: 31727 | C33: 38 | D33: 42464 | E33: Job Portal | F33: D_005 | G33: Distribution Manager | H33: Full-Time | I33: MGR105 | J33: 850000 | K33: 82000 | L33: =SUM(J33:K33) -> 932000 | M33: 16 | N33: 4.3 | O33: 97.7 | P33: 3 | Q33: No | R33: Low | S33: 44301 | T33: Active | U33: =VLOOKUP(A33,Emp_Info!$B$1:$G$101,3,0) -> akash | V33: =_xlfn.XLOOKUP(A33,Emp_Info!$B$2:$B$101,Emp_Info!$A$2:$A$101,,0) -> yadav | W33: =PROPER(_xlfn.CONCAT(U33," ",V33)) -> Akash Yadav | X33: =UPPER(_xlfn.CONCAT(LEFT(U33),LEFT(V33),RIGHT(A33,3))) -> AY089 | Y33: =HLOOKUP(F33,Dept_Info!$A$2:$I$3,2,0) -> Marketing | Z33: =IF(Y33="Sales",L33+(L33*$AG$6),L33) -> 932000 | AA33: =IF(J33<700000,"Low",IF(AND(J33>700000,J33<900000),"Medium","High")) -> Medium | AB33: Male | AC33: =INDEX(Emp_Info!$B$1:$G$101,MATCH(HR_Data!$A72,Emp_Info!$B$2:$B$101,0),MATCH(HR_Data!AC$1,Emp_Info!$B$1:$G$1,0)) -> Bachelor | AD33: =INDEX(Emp_Info!$A$1:$G$101,MATCH(HR_Data!$A33,Emp_Info!$B$1:$B$101,0),MATCH(HR_Data!AD$1,Emp_Info!$A$1:$G$1,0)) -> Noida | AE33: =INDEX(Emp_Info!$A$1:$G$101,MATCH(HR_Data!$A33,Emp_Info!$B$1:$B$101,0),MATCH(HR_Data!AE$1,Emp_Info!$A$1:$G$1,0)) -> North | AF33: =IF(AND(P33>=3,M33>6),"Eligible","Not Eligible") -> Eligible
A34: EMP035 | B34: 32706 | C34: 35 | D34: 43233 | E34: LinkedIn | F34: D_005 | G34: Quality Manager | H34: Full-Time | I34: MGR105 | J34: 850000 | K34: 82000 | L34: =SUM(J34:K34) -> 932000 | M34: 12 | N34: 4.3 | O34: 97.6 | P34: 3 | Q34: Yes | R34: Low | S34: 45066 | T34: Active | U34: =VLOOKUP(A34,Emp_Info!$B$1:$G$101,3,0) -> manish | V34: =_xlfn.XLOOKUP(A34,Emp_Info!$B$2:$B$101,Emp_Info!$A$2:$A$101,,0) -> goyal | W34: =PROPER(_xlfn.CONCAT(U34," ",V34)) -> Manish Goyal | X34: =UPPER(_xlfn.CONCAT(LEFT(U34),LEFT(V34),RIGHT(A34,3))) -> MG035 | Y34: =HLOOKUP(F34,Dept_Info!$A$2:$I$3,2,0) -> Marketing | Z34: =IF(Y34="Sales",L34+(L34*$AG$6),L34) -> 932000 | AA34: =IF(J34<700000,"Low",IF(AND(J34>700000,J34<900000),"Medium","High")) -> Medium | AB34: Male | AC34: =INDEX(Emp_Info!$B$1:$G$101,MATCH(HR_Data!$A79,Emp_Info!$B$2:$B$101,0),MATCH(HR_Data!AC$1,Emp_Info!$B$1:$G$1,0)) -> Bachelor | AD34: =INDEX(Emp_Info!$A$1:$G$101,MATCH(HR_Data!$A34,Emp_Info!$B$1:$B$101,0),MATCH(HR_Data!AD$1,Emp_Info!$A$1:$G$1,0)) -> Chennai | AE34: =INDEX(Emp_Info!$A$1:$G$101,MATCH(HR_Data!$A34,Emp_Info!$B$1:$B$101,0),MATCH(HR_Data!AE$1,Emp_Info!$A$1:$G$1,0)) -> South | AF34: =IF(AND(P34>=3,M34>6),"Eligible","Not Eligible") -> Eligible
A35: EMP095 | B35: 33110 | C35: 34 | D35: 43538 | E35: Job Portal | F35: D_004 | G35: Growth Marketing Manager | H35: Full-Time | I35: MGR104 | J35: 850000 | K35: 82000 | L35: =SUM(J35:K35) -> 932000 | M35: 10 | N35: 4.4 | O35: 97.8 | P35: 3 | Q35: Yes | R35: Low | S35: NA | T35: Active | U35: =VLOOKUP(A35,Emp_Info!$B$1:$G$101,3,0) -> puneet | V35: =_xlfn.XLOOKUP(A35,Emp_Info!$B$2:$B$101,Emp_Info!$A$2:$A$101,,0) -> mehta | W35: =PROPER(_xlfn.CONCAT(U35," ",V35)) -> Puneet Mehta | X35: =UPPER(_xlfn.CONCAT(LEFT(U35),LEFT(V35),RIGHT(A35,3))) -> PM095 | Y35: =HLOOKUP(F35,Dept_Info!$A$2:$I$3,2,0) -> Admin | Z35: =IF(Y35="Sales",L35+(L35*$AG$6),L35) -> 932000 | AA35: =IF(J35<700000,"Low",IF(AND(J35>700000,J35<900000),"Medium","High")) -> Medium | AB35: Male | AC35: =INDEX(Emp_Info!$B$1:$G$101,MATCH(HR_Data!$A2,Emp_Info!$B$2:$B$101,0),MATCH(HR_Data!AC$1,Emp_Info!$B$1:$G$1,0)) -> Bachelor | AD35: =INDEX(Emp_Info!$A$1:$G$101,MATCH(HR_Data!$A35,Emp_Info!$B$1:$B$101,0),MATCH(HR_Data!AD$1,Emp_Info!$A$1:$G$1,0)) -> Hyderabad | AE35: =INDEX(Emp_Info!$A$1:$G$101,MATCH(HR_Data!$A35,Emp_Info!$B$1:$B$101,0),MATCH(HR_Data!AE$1,Emp_Info!$A$1:$G$1,0)) -> South | AF35: =IF(AND(P35>=3,M35>6),"Eligible","Not Eligible") -> Eligible
A36: EMP052 | B36: 33479 | C36: 33 | D36: 43636 | E36: Job Portal | F36: D_002 | G36: Talent Acquisition Manager | H36: Full-Time | I36: MGR102 | J36: 850000 | K36: 82000 | L36: =SUM(J36:K36) -> 932000 | M36: 9 | N36: 4.4 | O36: 97.8 | P36: 2 | Q36: Yes | R36: Low | S36: 45092 | T36: Active | U36: =VLOOKUP(A36,Emp_Info!$B$1:$G$101,3,0) -> aditi | V36: =_xlfn.XLOOKUP(A36,Emp_Info!$B$2:$B$101,Emp_Info!$A$2:$A$101,,0) -> malhotra | W36: =PROPER(_xlfn.CONCAT(U36," ",V36)) -> Aditi Malhotra | X36: =UPPER(_xlfn.CONCAT(LEFT(U36),LEFT(V36),RIGHT(A36,3))) -> AM052 | Y36: =HLOOKUP(F36,Dept_Info!$A$2:$I$3,2,0) -> HR | Z36: =IF(Y36="Sales",L36+(L36*$AG$6),L36) -> 932000 | AA36: =IF(J36<700000,"Low",IF(AND(J36>700000,J36<900000),"Medium","High")) -> Medium | AB36: Female | AC36: =INDEX(Emp_Info!$B$1:$G$101,MATCH(HR_Data!$A37,Emp_Info!$B$2:$B$101,0),MATCH(HR_Data!AC$1,Emp_Info!$B$1:$G$1,0)) -> Bachelor | AD36: =INDEX(Emp_Info!$A$1:$G$101,MATCH(HR_Data!$A36,Emp_Info!$B$1:$B$101,0),MATCH(HR_Data!AD$1,Emp_Info!$A$1:$G$1,0)) -> Mumbai | AE36: =INDEX(Emp_Info!$A$1:$G$101,MATCH(HR_Data!$A36,Emp_Info!$B$1:$B$101,0),MATCH(HR_Data!AE$1,Emp_Info!$A$1:$G$1,0)) -> West | AF36: =IF(AND(P36>=3,M36>6),"Eligible","Not Eligible") -> Not Eligible
A37: EMP068 | B37: 33441 | C37: 33 | D37: 43756 | E37: Job Portal | F37: D_001 | G37: Scrum Master | H37: Full-Time | I37: MGR101 | J37: 850000 | K37: 82000 | L37: =SUM(J37:K37) -> 932000 | M37: 9 | N37: 4.4 | O37: 97.7 | P37: 3 | Q37: Yes | R37: Low | S37: NA | T37: Active | U37: =VLOOKUP(A37,Emp_Info!$B$1:$G$101,3,0) -> rashmi | V37: =_xlfn.XLOOKUP(A37,Emp_Info!$B$2:$B$101,Emp_Info!$A$2:$A$101,,0) -> kapoor | W37: =PROPER(_xlfn.CONCAT(U37," ",V37)) -> Rashmi Kapoor | X37: =UPPER(_xlfn.CONCAT(LEFT(U37),LEFT(V37),RIGHT(A37,3))) -> RK068 | Y37: =HLOOKUP(F37,Dept_Info!$A$2:$I$3,2,0) -> IT | Z37: =IF(Y37="Sales",L37+(L37*$AG$6),L37) -> 932000 | AA37: =IF(J37<700000,"Low",IF(AND(J37>700000,J37<900000),"Medium","High")) -> Medium | AB37: Female | AC37: =INDEX(Emp_Info!$B$1:$G$101,MATCH(HR_Data!$A58,Emp_Info!$B$2:$B$101,0),MATCH(HR_Data!AC$1,Emp_Info!$B$1:$G$1,0)) -> Bachelor | AD37: =INDEX(Emp_Info!$A$1:$G$101,MATCH(HR_Data!$A37,Emp_Info!$B$1:$B$101,0),MATCH(HR_Data!AD$1,Emp_Info!$A$1:$G$1,0)) -> Bangalore | AE37: =INDEX(Emp_Info!$A$1:$G$101,MATCH(HR_Data!$A37,Emp_Info!$B$1:$B$101,0),MATCH(HR_Data!AE$1,Emp_Info!$A$1:$G$1,0)) -> South | AF37: =IF(AND(P37>=3,M37>6),"Eligible","Not Eligible") -> Eligible
A38: EMP085 | B38: 33045 | C38: 34 | D38: 43476 | E38: Job Portal | F38: D_003 | G38: Partner Manager | H38: Full-Time | I38: MGR106 | J38: 840000 | K38: 88000 | L38: =SUM(J38:K38) -> 928000 | M38: 10 | N38: 4.3 | O38: 97 | P38: 2 | Q38: Yes | R38: Low | S38: 44946 | T38: Active | U38: =VLOOKUP(A38,Emp_Info!$B$1:$G$101,3,0) -> anuj | V38: =_xlfn.XLOOKUP(A38,Emp_Info!$B$2:$B$101,Emp_Info!$A$2:$A$101,,0) -> sinha | W38: =PROPER(_xlfn.CONCAT(U38," ",V38)) -> Anuj Sinha | X38: =UPPER(_xlfn.CONCAT(LEFT(U38),LEFT(V38),RIGHT(A38,3))) -> AS085 | Y38: =HLOOKUP(F38,Dept_Info!$A$2:$I$3,2,0) -> Sales | Z38: =IF(Y38="Sales",L38+(L38*$AG$6),L38) -> 1067200 | AA38: =IF(J38<700000,"Low",IF(AND(J38>700000,J38<900000),"Medium","High")) -> Medium | AB38: Male | AC38: =INDEX(Emp_Info!$B$1:$G$101,MATCH(HR_Data!$A98,Emp_Info!$B$2:$B$101,0),MATCH(HR_Data!AC$1,Emp_Info!$B$1:$G$1,0)) -> Bachelor | AD38: =INDEX(Emp_Info!$A$1:$G$101,MATCH(HR_Data!$A38,Emp_Info!$B$1:$B$101,0),MATCH(HR_Data!AD$1,Emp_Info!$A$1:$G$1,0)) -> Delhi | AE38: =INDEX(Emp_Info!$A$1:$G$101,MATCH(HR_Data!$A38,Emp_Info!$B$1:$B$101,0),MATCH(HR_Data!AE$1,Emp_Info!$A$1:$G$1,0)) -> North | AF38: =IF(AND(P38>=3,M38>6),"Eligible","Not Eligible") -> Not Eligible
A39: EMP043 | B39: 31796 | C39: 37 | D39: 42408 | E39: LinkedIn | F39: D_003 | G39: Territory Manager | H39: Full-Time | I39: MGR106 | J39: 830000 | K39: 92000 | L39: =SUM(J39:K39) -> 922000 | M39: 15 | N39: 4.3 | O39: 97.1 | P39: 2 | Q39: Yes | R39: Low | S39: 44242 | T39: Active | U39: =VLOOKUP(A39,Emp_Info!$B$1:$G$101,3,0) -> harish | V39: =_xlfn.XLOOKUP(A39,Emp_Info!$B$2:$B$101,Emp_Info!$A$2:$A$101,,0) -> menon | W39: =PROPER(_xlfn.CONCAT(U39," ",V39)) -> Harish Menon | X39: =UPPER(_xlfn.CONCAT(LEFT(U39),LEFT(V39),RIGHT(A39,3))) -> HM043 | Y39: =HLOOKUP(F39,Dept_Info!$A$2:$I$3,2,0) -> Sales | Z39: =IF(Y39="Sales",L39+(L39*$AG$6),L39) -> 1060300 | AA39: =IF(J39<700000,"Low",IF(AND(J39>700000,J39<900000),"Medium","High")) -> Medium | AB39: Male | AC39: =INDEX(Emp_Info!$B$1:$G$101,MATCH(HR_Data!$A88,Emp_Info!$B$2:$B$101,0),MATCH(HR_Data!AC$1,Emp_Info!$B$1:$G$1,0)) -> Master | AD39: =INDEX(Emp_Info!$A$1:$G$101,MATCH(HR_Data!$A39,Emp_Info!$B$1:$B$101,0),MATCH(HR_Data!AD$1,Emp_Info!$A$1:$G$1,0)) -> Chennai | AE39: =INDEX(Emp_Info!$A$1:$G$101,MATCH(HR_Data!$A39,Emp_Info!$B$1:$B$101,0),MATCH(HR_Data!AE$1,Emp_Info!$A$1:$G$1,0)) -> South | AF39: =IF(AND(P39>=3,M39>6),"Eligible","Not Eligible") -> Not Eligible
A40: EMP013 | B40: 33204 | C40: 34 | D40: 43306 | E40: Job Portal | F40: D_003 | G40: Business Development Manager | H40: Full-Time | I40: MGR106 | J40: 810000 | K40: 95000 | L40: =SUM(J40:K40) -> 905000 | M40: 10 | N40: 4.2 | O40: 95.5 | P40: 2 | Q40: Yes | R40: Medium | S40: NA | T40: Active | U40: =VLOOKUP(A40,Emp_Info!$B$1:$G$101,3,0) -> arjun | V40: =_xlfn.XLOOKUP(A40,Emp_Info!$B$2:$B$101,Emp_Info!$A$2:$A$101,,0) -> rao | W40: =PROPER(_xlfn.CONCAT(U40," ",V40)) -> Arjun Rao | X40: =UPPER(_xlfn.CONCAT(LEFT(U40),LEFT(V40),RIGHT(A40,3))) -> AR013 | Y40: =HLOOKUP(F40,Dept_Info!$A$2:$I$3,2,0) -> Sales | Z40: =IF(Y40="Sales",L40+(L40*$AG$6),L40) -> 1040750 | AA40: =IF(J40<700000,"Low",IF(AND(J40>700000,J40<900000),"Medium","High")) -> Medium | AB40: Male | AC40: =INDEX(Emp_Info!$B$1:$G$101,MATCH(HR_Data!$A96,Emp_Info!$B$2:$B$101,0),MATCH(HR_Data!AC$1,Emp_Info!$B$1:$G$1,0)) -> Bachelor | AD40: =INDEX(Emp_Info!$A$1:$G$101,MATCH(HR_Data!$A40,Emp_Info!$B$1:$B$101,0),MATCH(HR_Data!AD$1,Emp_Info!$A$1:$G$1,0)) -> Hyderabad | AE40: =INDEX(Emp_Info!$A$1:$G$101,MATCH(HR_Data!$A40,Emp_Info!$B$1:$B$101,0),MATCH(HR_Data!AE$1,Emp_Info!$A$1:$G$1,0)) -> South | AF40: =IF(AND(P40>=3,M40>6),"Eligible","Not Eligible") -> Not Eligible
...

Sheet Dept_Info
A1: HOD | B1: Shantanu Roy | C1: Vibha Kaur | D1: Nikhil Chopra | E1: Mohanty Sahoo | F1: Akash Wadhwa | G1: Ankush Patel | H1: Pankaj Singh | I1: Martyn John
A2: Dept_ID | B2: D_001 | C2: D_002 | D2: D_003 | E2: D_004 | F2: D_005 | G2: D_006 | H2: D_007 | I2: D_008
A3: Dept_Name | B3: IT | C3: HR | D3: Sales | E3: Admin | F3: Marketing | G3: Finance | H3: Operations | I3: R&D

Sheet Emp_Info
A1: Last_Name | B1: Emp_ID | C1: Gender | D1: First_Name | E1: Education_Level | F1: Location | G1: Region
A2: gupta | B2: EMP011 | C2: Male | D2: manoj | E2: Bachelor | F2: Noida | G2: North
A3: kapoor | B3: EMP012 | C3: Female | D3: pooja | E3: Bachelor | F3: Pune | G3: West
A4: rao | B4: EMP013 | C4: Male | D4: arjun | E4: Master | F4: Hyderabad | G4: South
A5: verma | B5: EMP014 | C5: Female | D5: neha | E5: Bachelor | F5: Bangalore | G5: South
A6: malhotra | B6: EMP015 | C6: Male | D6: karan | E6: Master | F6: Delhi | G6: North
A7: saxena | B7: EMP016 | C7: F | D7: ritu | E7: Bachelor | F7: Mumbai | G7: West
A8: pillai | B8: EMP017 | C8: Male | D8: sanjay | E8: Bachelor | F8: Chennai | G8: South
A9: bhat | B9: EMP018 | C9: Female | D9: meera | E9: Bachelor | F9: Pune | G9: West
A10: chopra | B10: EMP019 | C10: Male | D10: anil | E10: Master | F10: Noida | G10: North
A11: menon | B11: EMP020 | C11: F | D11: divya | E11: Bachelor | F11: Bangalore | G11: South
A12: kumar | B12: EMP001 | C12: Male | D12: rajesh | E12: Bachelor | F12: Mumbai | G12: West
... A101: pillai | B101: EMP092 | C101: Female | D101: kavita | E101: Master | F101: Bangalore | G101: South

Sheet Class_3_File
A1: Emp_ID | B1: Date_of_Birth | C1: Age | D1: Hire_Date | E1: Hiring Source | F1: Dept_ID | G1: Job_Title | H1: Employment_Type | I1: Manager_ID | J1: Base_Salary | K1: Bonus | L1: Total_Salary | M1: Years_of_Experience | N1: Performance_Rating | O1: Attendance_Percentage | P1: Certifications | Q1: Promotion_Eligible | R1: Attrition_Risk | S1: Last_Promotion_Date | T1: Employee_Status | U1: First_Name | V1: Last_Name | W1: Full_Name | X1: ID_Card_Details | Y1: Dept_Name | Z1: Diwali_Month_Salary | AA1: Salary_Seg | AB1: Gender | AC1: Education_Level | AD1: Location | AE1: Region | AF1: Advanced_Cert_Bonus
A2: EMP075 | B2: 31339 | C2: 39 | D2: 41983 | E2: Referral | F2: D_006 | G2: VP Finance | H2: Full-Time | I2: MGR103 | J2: 1450000 | K2: 165000 | L2: 1615000 | M2: 19 | N2: 4.8 | O2: 99.1 | P2: 4 | Q2: No | R2: Low | S2: 43819 | T2: Active | U2: vinay | V2: reddy | W2: Vinay Reddy | X2: VR075 | Y2: Finance | Z2: 1615000 | AA2: High | AB2: Male | AC2: Bachelor | AD2: Chennai | AE2: South | AF2: Eligible
A3: EMP019 | B3: 31301 | C3: 39 | D3: 42070 | E3: Job Portal | F3: D_001 | G3: IT Manager | H3: Full-Time | I3: MGR101 | J3: 1450000 | K3: 165000 | L3: 1615000 | M3: 17 | N3: 4.8 | O3: 99.2 | P3: 5 | Q3: No | R3: Low | S3: 43905 | T3: Active | U3: anil | V3: chopra | W3: Anil Chopra | X3: AC019 | Y3: IT | Z3: 1615000 | AA3: High | AB3: Male | AC3: Master | AD3: Noida | AE3: North | AF3: Eligible
A4: EMP097 | B4: 31462 | D4: 42137 | E4: Referral | F4: D_003 | G4: VP Sales | H4: Full-Time | I4: MGR106 | J4: 1380000 | K4: 158000 | L4: 1538000 | M4: 18 | N4: 4.8 | O4: 99 | P4: 4 | Q4: No | R4: Low | S4: 43971 | T4: Active | U4: rohit | V4: agarwal | W4: Rohit Agarwal | X4: RA097 | Y4: Sales | Z4: 1768700 | AA4: High | AB4: Male | AC4: Master | AD4: Bangalore | AE4: South | AF4: Eligible
A5: EMP005 | B5: 32129 | C5: 37 | D5: 42559 | E5: Campus | F5: D_005 | G5: Operations Manager | H5: Full-Time | I5: MGR105 | J5: 1100000 | K5: 120000 | L5: 1220000 | M5: 15 | N5: 4.7 | O5: 99 | P5: 4 | Q5: No | R5: Low | S5: 44397 | T5: Active | U5: vikram | V5: singh | W5: Vikram Singh | X5: VS005 | Y5: Marketing | Z5: 1220000 | AA5: High | AB5: Male | AC5: Bachelor | AD5: Pune | AE5: West | AF5: Eligible
A6: EMP047 | B6: 31355 | C6: 39 | D6: 42115 | E6: LinkedIn | F6: D_005 | G6: Plant Manager | H6: Full-Time | I6: MGR105 | J6: 1080000 | K6: 115000 | L6: 1195000 | M6: 18 | N6: 4.6 | O6: 98.6 | P6: 4 | Q6: No | R6: Low | S6: 43931 | T6: Active | U6: rajeev | V6: bose | W6: Rajeev Bose | X6: RB047 | Y6: Marketing | Z6: 1195000 | AA6: High | AB6: Male | AC6: Bachelor | AD6: Pune | AE6: West | AF6: Eligible
A7: EMP041 | B7: 33015 | C7: 34 | D7: 43419 | E7: Freelance | F7: D_001 | G7: Cloud Architect | H7: Full-Time | I7: MGR101 | J7: 1050000 | K7: 110000 | L7: 1160000 | M7: 11 | N7: 4.7 | O7: 98.9 | P7: 5 | Q7: Yes | R7: Low | S7: 44885 | T7: Active | U7: varun | V7: kapoor | W7: Varun Kapoor | X7: VK041 | Y7: IT | Z7: 1160000 | AA7: High | AB7: Male | AC7: Bachelor | AD7: Noida | AE7: North | AF7: Eligible
A8: EMP009 | B8: 31654 | C8: 38 | D8: 42040 | E8: Referral | F8: D_006 | G8: Finance Manager | H8: Full-Time | I8: MGR103 | J8: 1050000 | K8: 105000 | L8: 1155000 | M8: 16 | N8: 4.6 | O8: 98.5 | P8: 3 | Q8: No | R8: Low | S8: 43871 | T8: Active | U8: suresh | V8: nair | W8: Suresh Nair | X8: SN009 | Y8: Finance | Z8: 1155000 | AA8: High | AB8: Male | AC8: Master | AD8: Chennai | AE8: South | AF8: Eligible
A9: EMP079 | B9: 32516 | C9: 35 | D9: 43329 | E9: Job Portal | F9: D_003 | G9: National Sales Manager | H9: Full-Time | I9: MGR106 | J9: 1020000 | K9: 125000 | L9: 1145000 | M9: 12 | N9: 4.7 | O9: 98.6 | P9: 3 | Q9: Yes | R9: Low | S9: 45163 | T9: Active | U9: nikhil | V9: chopra | W9: Nikhil Chopra | X9: NC079 | Y9: Sales | Z9: 1316750 | AA9: High | AB9: Male | AC9: Master | AD9: Hyderabad | AE9: South | AF9: Eligible
A10: EMP051 | B10: 31537 | C10: 38 | D10: 42383 | E10: Freelance | F10: D_006 | G10: Controller | H10: Full-Time | I10: MGR103 | J10: 980000 | K10: 98000 | L10: 1078000 | M10: 16 | N10: 4.5 | O10: 98.2 | P10: 3 | Q10: No | R10: Low | S10: 44216 | T10: Active | U10: ramesh | V10: pillai | W10: Ramesh Pillai | X10: RP051 | Y10: Finance | Z10: 1078000 | AA10: High | AB10: Male | AC10: Master | AD10: Chennai | AE10: South | AF10: Eligible
A11: EMP077 | B11: 32276 | C11: 36 | D11: 43053 | E11: LinkedIn | F11: D_001 | G11: Solutions Architect | H11: Full-Time | I11: MGR101 | J11: 980000 | K11: 98000 | L11: 1078000 | M11: 13 | N11: 4.6 | O11: 98.4 | P11: 4 | Q11: Yes | R11: Low | S11: 44885 | T11: Active | U11: rajat | V11: verma | W11: Rajat Verma | X11: RV077 | Y11: IT | Z11: 1078000 | AA11: High | AB11: Male | AC11: Master | AD11: Delhi | AE11: North | AF11: Eligible
A12: EMP025 | B12: 33206 | C12: 34 | D12: 43544 | E12: Job Portal | F12: D_003 | G12: Regional Sales Manager | H12: Full-Time | I12: MGR106 | J12: 950000 | K12: 115000 | L12: 1065000 | M12: 10 | N12: 4.5 | O12: 97.8 | P12: 2 | Q12: Yes | R12: Low | S12: 44995 | T12: Active | U12: gaurav | V12: pandey | W12: Gaurav Pandey | X12: GP025 | Y12: Sales | Z12: 1224750 | AA12: High | AB12: Male | AC12: Master | AD12: Hyderabad | AE12: South | AF12: Not Eligible
A13: EMP061 | B13: 32504 | C13: 36 | D13: 42954 | E13: Referral | F13: D_003 | G13: Enterprise Sales Manager | H13: Full-Time | I13: MGR106 | J13: 940000 | K13: 112000 | L13: 1052000 | M13: 13 | N13: 4.5 | O13: 98.1 | P13: 3 | Q13: Yes | R13: Low | S13: 44788 | T13: Active | U13: siddharth | V13: mehta | W13: Siddharth Mehta | X13: SM061 | Y13: Sales | Z13: 1209800 | AA13: High | AB13: Male | AC13: Bachelor | AD13: Delhi | AE13: North | AF13: Eligible
A14: EMP002 | B14: 33076 | C14: 34 | D14: 43631 | E14: LinkedIn | F14: D_002 | G14: HR Manager | H14: Full-Time | I14: MGR102 | J14: 950000 | K14: 95000 | L14: 1045000 | M14: 10 | N14: 4.3 | O14: 98.2 | P14: 2 | Q14: Yes | R14: Low | S14: 45087 | T14: Active | U14: priya | V14: sharma | W14: Priya Sharma | X14: PS002 | Y14: HR | Z14: 1045000 | AA14: High | AB14: Female | AC14: Bachelor | AD14: Delhi | AE14: North | AF14: Not Eligible
A15: EMP092 | B15: 34168 | C15: 31 | D15: 44462 | E15: Job Portal | F15: D_001 | G15: Machine Learning Engineer | H15: Full-Time | I15: MGR101 | J15: 950000 | K15: 95000 | L15: 1045000 | M15: 6 | N15: 4.6 | O15: 98.3 | P15: 4 | Q15: Yes | R15: Low | S15: NA | T15: Active | U15: kavita | V15: pillai | W15: Kavita Pillai | X15: KP092 | Y15: IT | Z15: 1045000 | AA15: High | AB15: Female | AC15: Bachelor | AD15: Bangalore | AE15: South | AF15: Not Eligible
A16: EMP036 | B16: 33490 | C16: 33 | D16: 43851 | E16: Referral | F16: D_004 | G16: Product Manager | H16: Full-Time | I16: MGR104 | J16: 920000 | K16: 95000 | L16: 1015000 | M16: 9 | N16: 4.6 | O16: 98.7 | P16: 3 | Q16: Yes | R16: Low | S16: NA | T16: Active | U16: pallavi | V16: nambiar | W16: Pallavi Nambiar | X16: PN036 | Y16: Admin | Z16: 1015000 | AA16: High | AB16: Female | AC16: Bachelor | AD16: Pune | AE16: West | AF16: Eligible
A17: EMP011 | B17: 30684 | C17: 40 | D17: 41988 | E17: Freelance | F17: D_001 | G17: Senior Developer | H17: Full-Time | I17: MGR101 | J17: 920000 | K17: 92000 | L17: 1012000 | M17: 18 | N17: 4.4 | O17: 97.3 | P17: 4 | Q17: No | R17: Low | S17: 43819 | T17: Active | U17: manoj | V17: gupta | W17: Manoj Gupta | X17: MG011 | Y17: IT | Z17: 1012000 | AA17: High | AB17: Male | AC17: Bachelor | AD17: Noida | AE17: North | AF17: Eligible
A18: EMP059 | B18: 31479 | C18: 38 | D18: 42300 | E18: Job Portal | F18: D_005 | G18: Production Manager | H18: Full-Time | I18: MGR105 | J18: 920000 | K18: 92000 | L18: 1012000 | M18: 17 | N18: 4.4 | O18: 97.9 | P18: 3 | Q18: No | R18: Low | S18: 44119 | T18: Active | U18: alok | V18: sinha | W18: Alok Sinha | X18: AS059 | Y18: Marketing | Z18: 1012000 | AA18: High | AB18: Male | AC18: Master | AD18: Chennai | AE18: South | AF18: Eligible
A19: EMP093 | B19: 32080 | C19: 37 | D19: 42531 | E19: Freelance | F19: D_006 | G19: Financial Planning Manager | H19: Full-Time | I19: MGR103 | J19: 920000 | K19: 92000 | L19: 1012000 | M19: 15 | N19: 4.5 | O19: 98 | P19: 3 | Q19: Yes | R19: Low | S19: 44367 | T19: Active | U19: dinesh | V19: reddy | W19: Dinesh Reddy | X19: DR093 | Y19: Finance | Z19: 1012000 | AA19: High | AB19: Male | AC19: Master | AD19: Delhi | AE19: North | AF19: Eligible
A20: EMP096 | B20: 33579 | C20: 33 | D20: 43758 | E20: Freelance | F20: D_001 | G20: Technical Lead | H20: Full-Time | I20: MGR101 | J20: 920000 | K20: 92000 | L20: 1012000 | M20: 9 | N20: 4.5 | O20: 98.1 | P20: 4 | Q20: Yes | R20: Low | S20: 45214 | T20: Active | U20: anjana | V20: nair | W20: Anjana Nair | X20: AN096 | Y20: IT | Z20: 1012000 | AA20: High | AB20: Female | AC20: Master | AD20: Noida | AE20: North | AF20: Eligible
A21: EMP082 | B21: 34530 | C21: 30 | D21: 44862 | E21: Job Portal | F21: D_001 | G21: Data Scientist | H21: Full-Time | I21: MGR101 | J21: 920000 | K21: 92000 | L21: 1012000 | M21: 5 | N21: 4.5 | O21: 97.8 | P21: 3 | Q21: Yes | R21: Low | S21: NA | T21: Active | U21: namita | V21: rao | W21: Namita Rao | X21: NR082 | Y21: IT | Z21: 1012000 | AA21: High | AB21: Female | AC21: Master | AD21: Noida | AE21: North | AF21: Not Eligible
A22: EMP049 | B22: 32199 | C22: 36 | D22: 42622 | E22: Freelance | F22: D_003 | G22: Channel Sales Manager | H22: Full-Time | I22: MGR106 | J22: 890000 | K22: 105000 | L22: 995000 | M22: 14 | N22: 4.4 | O22: 97.5 | P22: 3 | Q22: Yes | R22: Low | S22: 44459 | T22: Active | U22: sunil | V22: agarwal | W22: Sunil Agarwal | X22: SA049 | Y22: Sales | Z22: 1144250 | AA22: Medium | AB22: Male | AC22: Bachelor | AD22: Bangalore | AE22: South | AF22: Eligible
A23: EMP007 | B23: 32673 | C23: 35 | D23: 43434 | E23: Job Portal | F23: D_003 | G23: Sales Manager | H23: Full-Time | I23: MGR106 | J23: 880000 | K23: 110000 | L23: 990000 | M23: 11 | N23: 4.3 | O23: 96.7 | P23: 1 | Q23: Yes | R23: Medium | S23: 44880 | T23: Active | U23: rahul | V23: mehta | W23: Rahul Mehta | X23: RM007 | Y23: Sales | Z23: 1138500 | AA23: Medium | AB23: Male | AC23: Bachelor | AD23: Delhi | AE23: North | AF23: Not Eligible
